2025-03-21 08:55:46,484 - ERROR - Unhandled exception occurred
Traceback (most recent call last):
  File "/Users/bytedance/dev/rag/venv/lib/python3.9/site-packages/anyio/streams/memory.py", line 98, in receive
    return self.receive_nowait()
  File "/Users/bytedance/dev/rag/venv/lib/python3.9/site-packages/anyio/streams/memory.py", line 93, in receive_nowait
    raise WouldBlock
anyio.WouldBlock

During handling of the above exception, another exception occurred:

Traceback (most recent call last):
  File "/Users/bytedance/dev/rag/venv/lib/python3.9/site-packages/starlette/middleware/base.py", line 147, in call_next
    message = await recv_stream.receive()
  File "/Users/bytedance/dev/rag/venv/lib/python3.9/site-packages/anyio/streams/memory.py", line 118, in receive
    raise EndOfStream
anyio.EndOfStream

During handling of the above exception, another exception occurred:

Traceback (most recent call last):
  File "/Users/bytedance/dev/rag/middleware/log_middleware.py", line 24, in dispatch
    response = await call_next(request)
  File "/Users/bytedance/dev/rag/venv/lib/python3.9/site-packages/starlette/middleware/base.py", line 153, in call_next
    raise app_exc
  File "/Users/bytedance/dev/rag/venv/lib/python3.9/site-packages/starlette/middleware/base.py", line 140, in coro
    await self.app(scope, receive_or_disconnect, send_no_error)
  File "/Users/bytedance/dev/rag/venv/lib/python3.9/site-packages/starlette/middleware/exceptions.py", line 62, in __call__
    await wrap_app_handling_exceptions(self.app, conn)(scope, receive, send)
  File "/Users/bytedance/dev/rag/venv/lib/python3.9/site-packages/starlette/_exception_handler.py", line 53, in wrapped_app
    raise exc
  File "/Users/bytedance/dev/rag/venv/lib/python3.9/site-packages/starlette/_exception_handler.py", line 42, in wrapped_app
    await app(scope, receive, sender)
  File "/Users/bytedance/dev/rag/venv/lib/python3.9/site-packages/starlette/routing.py", line 714, in __call__
    await self.middleware_stack(scope, receive, send)
  File "/Users/bytedance/dev/rag/venv/lib/python3.9/site-packages/starlette/routing.py", line 734, in app
    await route.handle(scope, receive, send)
  File "/Users/bytedance/dev/rag/venv/lib/python3.9/site-packages/starlette/routing.py", line 288, in handle
    await self.app(scope, receive, send)
  File "/Users/bytedance/dev/rag/venv/lib/python3.9/site-packages/starlette/routing.py", line 76, in app
    await wrap_app_handling_exceptions(app, request)(scope, receive, send)
  File "/Users/bytedance/dev/rag/venv/lib/python3.9/site-packages/starlette/_exception_handler.py", line 53, in wrapped_app
    raise exc
  File "/Users/bytedance/dev/rag/venv/lib/python3.9/site-packages/starlette/_exception_handler.py", line 42, in wrapped_app
    await app(scope, receive, sender)
  File "/Users/bytedance/dev/rag/venv/lib/python3.9/site-packages/starlette/routing.py", line 73, in app
    response = await f(request)
  File "/Users/bytedance/dev/rag/venv/lib/python3.9/site-packages/fastapi/routing.py", line 301, in app
    raw_response = await run_endpoint_function(
  File "/Users/bytedance/dev/rag/venv/lib/python3.9/site-packages/fastapi/routing.py", line 214, in run_endpoint_function
    return await run_in_threadpool(dependant.call, **values)
  File "/Users/bytedance/dev/rag/venv/lib/python3.9/site-packages/starlette/concurrency.py", line 37, in run_in_threadpool
    return await anyio.to_thread.run_sync(func)
  File "/Users/bytedance/dev/rag/venv/lib/python3.9/site-packages/anyio/to_thread.py", line 33, in run_sync
    return await get_asynclib().run_sync_in_worker_thread(
  File "/Users/bytedance/dev/rag/venv/lib/python3.9/site-packages/anyio/_backends/_asyncio.py", line 877, in run_sync_in_worker_thread
    return await future
  File "/Users/bytedance/dev/rag/venv/lib/python3.9/site-packages/anyio/_backends/_asyncio.py", line 807, in run
    result = context.run(func, *args)
  File "/Users/bytedance/dev/rag/api/chat_router.py", line 20, in chat_with_context
    raise ValueError("This is a test error")
ValueError: This is a test error
2025-03-21 08:56:24,739 - ERROR - Unhandled exception occurred
Traceback (most recent call last):
  File "/Users/bytedance/dev/rag/venv/lib/python3.9/site-packages/anyio/streams/memory.py", line 98, in receive
    return self.receive_nowait()
  File "/Users/bytedance/dev/rag/venv/lib/python3.9/site-packages/anyio/streams/memory.py", line 93, in receive_nowait
    raise WouldBlock
anyio.WouldBlock

During handling of the above exception, another exception occurred:

Traceback (most recent call last):
  File "/Users/bytedance/dev/rag/venv/lib/python3.9/site-packages/starlette/middleware/base.py", line 147, in call_next
    message = await recv_stream.receive()
  File "/Users/bytedance/dev/rag/venv/lib/python3.9/site-packages/anyio/streams/memory.py", line 118, in receive
    raise EndOfStream
anyio.EndOfStream

During handling of the above exception, another exception occurred:

Traceback (most recent call last):
  File "/Users/bytedance/dev/rag/middleware/log_middleware.py", line 24, in dispatch
    response = await call_next(request)
  File "/Users/bytedance/dev/rag/venv/lib/python3.9/site-packages/starlette/middleware/base.py", line 153, in call_next
    raise app_exc
  File "/Users/bytedance/dev/rag/venv/lib/python3.9/site-packages/starlette/middleware/base.py", line 140, in coro
    await self.app(scope, receive_or_disconnect, send_no_error)
  File "/Users/bytedance/dev/rag/venv/lib/python3.9/site-packages/starlette/middleware/exceptions.py", line 62, in __call__
    await wrap_app_handling_exceptions(self.app, conn)(scope, receive, send)
  File "/Users/bytedance/dev/rag/venv/lib/python3.9/site-packages/starlette/_exception_handler.py", line 53, in wrapped_app
    raise exc
  File "/Users/bytedance/dev/rag/venv/lib/python3.9/site-packages/starlette/_exception_handler.py", line 42, in wrapped_app
    await app(scope, receive, sender)
  File "/Users/bytedance/dev/rag/venv/lib/python3.9/site-packages/starlette/routing.py", line 714, in __call__
    await self.middleware_stack(scope, receive, send)
  File "/Users/bytedance/dev/rag/venv/lib/python3.9/site-packages/starlette/routing.py", line 734, in app
    await route.handle(scope, receive, send)
  File "/Users/bytedance/dev/rag/venv/lib/python3.9/site-packages/starlette/routing.py", line 288, in handle
    await self.app(scope, receive, send)
  File "/Users/bytedance/dev/rag/venv/lib/python3.9/site-packages/starlette/routing.py", line 76, in app
    await wrap_app_handling_exceptions(app, request)(scope, receive, send)
  File "/Users/bytedance/dev/rag/venv/lib/python3.9/site-packages/starlette/_exception_handler.py", line 53, in wrapped_app
    raise exc
  File "/Users/bytedance/dev/rag/venv/lib/python3.9/site-packages/starlette/_exception_handler.py", line 42, in wrapped_app
    await app(scope, receive, sender)
  File "/Users/bytedance/dev/rag/venv/lib/python3.9/site-packages/starlette/routing.py", line 73, in app
    response = await f(request)
  File "/Users/bytedance/dev/rag/venv/lib/python3.9/site-packages/fastapi/routing.py", line 301, in app
    raw_response = await run_endpoint_function(
  File "/Users/bytedance/dev/rag/venv/lib/python3.9/site-packages/fastapi/routing.py", line 214, in run_endpoint_function
    return await run_in_threadpool(dependant.call, **values)
  File "/Users/bytedance/dev/rag/venv/lib/python3.9/site-packages/starlette/concurrency.py", line 37, in run_in_threadpool
    return await anyio.to_thread.run_sync(func)
  File "/Users/bytedance/dev/rag/venv/lib/python3.9/site-packages/anyio/to_thread.py", line 33, in run_sync
    return await get_asynclib().run_sync_in_worker_thread(
  File "/Users/bytedance/dev/rag/venv/lib/python3.9/site-packages/anyio/_backends/_asyncio.py", line 877, in run_sync_in_worker_thread
    return await future
  File "/Users/bytedance/dev/rag/venv/lib/python3.9/site-packages/anyio/_backends/_asyncio.py", line 807, in run
    result = context.run(func, *args)
  File "/Users/bytedance/dev/rag/api/chat_router.py", line 20, in chat_with_context
    raise ValueError("This is a test error")
ValueError: This is a test error
